Workbook

Sheet README
A1: NASCAR Pre-Race Chatter Signal Workbook — 2025–2026
A2: Converted from F1 pre-race chatter template; driver-race scaffold for NASCAR Cup Series.
A4: Item | B4: Notes
A5: Purpose | B5: Create a NASCAR Cup pre-race chatter dataset that can be exported to CSV and joined to a race projection model.
A6: Scope | B6: 2025 full Cup Series and 2026 Cup Series through current race index, with scheduled remaining 2026 races scaffolded.
A7: Unit of analysis | B7: Driver-race, not team-race. This is because NASCAR model nudges will generally attach to drivers.
A8: What is scored | B8: Momentum, track fit, and context bundle. Scores are low-hanging, audit-friendly proxy scores from race results, standings, and pre-race source targets.
A9: Important limitation | B9: This is not a fully scraped article corpus. It is a starter/scaffold with results-backed event coding and search targets for pre-race articles, odds, and preview notes.
A10: How to use | B10: Review the Driver_Race_Signals sheet, update raw scores using pre-race sources, then export CSV_Output for the model.
A11: Primary sources | B11: Jayski results pages, NASCAR.com winners/standings/recaps, Racing-Reference season pages. Key URLs are retained in Source_Inventory.
A12: Last updated | B12: 2026-07-15 23:53

Sheet Dashboard
A1: NASCAR Pre-Race Chatter Dataset Dashboard
A2: Driver-level chatter signal scaffold for NASCAR Cup Series.
A4: Metric | B4: Value | C4: Notes | E4: Season | F4: Races | G4: Completed | H4: Drivers | I4: Driver-Race Rows | J4: Source Rows
A5: Seasons covered | B5: 2025–2026 | C5: 2025 complete; 2026 includes completed races through July 12 plus remaining scheduled race scaffold. | E5: 2025 | F5: 36 | G5: 36 | H5: 32 | I5: 1152 | J5: 180
A6: Race rows | B6: 72 | C6: Cup Series points races only; exhibition races excluded from Race_Index. | E6: 2026 | F6: 36 | G6: 20 | H6: 32 | I6: 1152 | J6: 180
A7: Driver universe | B7: 32 | C7: Top/full-time/high-signal Cup drivers for model join.
A8: Driver-race rows | B8: 2304 | C8: One row per driver per race.
A9: Source rows | B9: 360 | C9: Source targets retained for repeatable coding and auditability.
A10: Event-coded narratives | B10: 15 | C10: Manual event log applies major momentum/track-fit signals.
A11: CSV output rows | B11: 2304 | C11: CSV_Output is formula-driven from Driver_Race_Signals.
A12: Last update | B12: 2026-07-15 | C12: Built from uploaded F1 template; NASCAR source targets included.
A14: Notes | B14: Scores are intentionally conservative: use as model nudges, not a replacement for speed/odds/ratings. Review highlighted events before fitting.

Sheet Settings
A1: NASCAR Chatter Scoring Settings
A2: Weights and nudge conversions.
A4: Parameter | B4: Value | C4: Description
A5: Momentum_Weight | B5: 0.45 | C5: Positive/negative driver/team momentum mentions in pre-race articles or recent form.
A6: Track_Fit_Weight | B6: 0.35 | C6: Track-type match: road course, superspeedway, short track, intermediate.
A7: Context_Bundle_Weight | B7: 0.2 | C7: Driver confidence, qualifying/practice strength, reliability/penalty/injury/weather notes.
A8: Score_Cap_Abs | B8: 1 | C8: Caps final composite chatter score to [-cap, +cap].
A9: Default_Source_Confidence | B9: 0.75 | C9: Default proxy-coded source confidence before manual review.
A10: Points_Nudge_Per_Composite | B10: 4 | C10: Optional projected fantasy/model points nudge for +1 composite score.
A11: Finish_Position_Nudge_Per_Composite | B11: 1.5 | C11: Optional finish-position nudge; positive chatter reduces expected finish position.

Sheet Coding_Guide
A1: NASCAR Chatter Coding Guide
A2: Raw score buckets use -2 to +2 scale before weights and confidence.
A4: Bucket | B4: Raw signal scale | C4: Positive examples | D4: Negative examples | E4: Default weight
A5: Momentum | B5: -2 to +2 | C5: Driver/team described as gaining speed, consistently contending, strong recent finishes/wins, playoff push. | D5: Slump, DNFs, penalties, losing speed, declining team confidence. | E5: =Settings!B4
A6: Track_Fit | B6: -2 to +2 | C6: Strong history/current package on track type; road-course specialist on road course; superspeedway skill at Daytona/Talladega/Atlanta. | D6: Track type is a known weakness or team struggles with configuration. | E6: =Settings!B5
A7: Context Bundle | B7: -2 to +2 | C7: Positive practice/qualifying, crew-chief confidence, clean car, favorable weather/strategy narrative. | D7: Crash damage, engine/reliability concern, penalty, starting in back, driver discomfort. | E7: =Settings!B6
A8: Source Confidence | B8: 0 to 1 | C8: 1.0 for specific pre-race article/odds/news basis; 0.75 for results/form proxy; 0.50 for placeholder/source target only. | D8: N/A | E8: N/A

Sheet Race_Index
A1: Race_Key | B1: Season | C1: Round | D1: Race | E1: Race_Date | F1: Track | G1: Location | H1: Track_Type | I1: Status | J1: Winner | K1: Source_URL
A2: 2025_R01_DAYTONA_500 | B2: 2025 | C2: 1 | D2: Daytona 500 | E2: 45704 | F2: Daytona International Speedway | G2: Daytona Beach, FL | H2: Superspeedway | I2: Completed | J2: William Byron | K2: https://www.jayski.com/nascar-cup-series/2025-nascar-cup-series-race-results/
A3: 2025_R02_AMBETTER_HEALTH_400 | B3: 2025 | C3: 2 | D3: Ambetter Health 400 | E3: 45711 | F3: Atlanta Motor Speedway | G3: Hampton, GA | H3: Drafting intermediate | I3: Completed | J3: Christopher Bell | K3: https://www.jayski.com/nascar-cup-series/2025-nascar-cup-series-race-results/
A4: 2025_R03_ECHOPARK_TEXAS_GRAND_PRIX | B4: 2025 | C4: 3 | D4: EchoPark Texas Grand Prix | E4: 45718 | F4: Circuit of The Americas | G4: Austin, TX | H4: Road course | I4: Completed | J4: Christopher Bell | K4: https://www.jayski.com/nascar-cup-series/2025-nascar-cup-series-race-results/
A5: 2025_R04_SHRINERS_CHILDREN_S_500 | B5: 2025 | C5: 4 | D5: Shriners Children's 500 | E5: 45725 | F5: Phoenix Raceway | G5: Avondale, AZ | H5: Short/flat | I5: Completed | J5: Christopher Bell | K5: https://www.jayski.com/nascar-cup-series/2025-nascar-cup-series-race-results/
A6: 2025_R05_PENNZOIL_400 | B6: 2025 | C6: 5 | D6: Pennzoil 400 | E6: 45732 | F6: Las Vegas Motor Speedway | G6: Las Vegas, NV | H6: Intermediate | I6: Completed | J6: Josh Berry | K6: https://www.jayski.com/nascar-cup-series/2025-nascar-cup-series-race-results/
A7: 2025_R06_STRAIGHT_TALK_WIRELESS_400 | B7: 2025 | C7: 6 | D7: Straight Talk Wireless 400 | E7: 45739 | F7: Homestead-Miami Speedway | G7: Homestead, FL | H7: Intermediate | I7: Completed | J7: Kyle Larson | K7: https://www.jayski.com/nascar-cup-series/2025-nascar-cup-series-race-results/
A8: 2025_R07_COOK_OUT_400 | B8: 2025 | C8: 7 | D8: Cook Out 400 | E8: 45746 | F8: Martinsville Speedway | G8: Ridgeway, VA | H8: Short track | I8: Completed | J8: Denny Hamlin | K8: https://www.jayski.com/nascar-cup-series/2025-nascar-cup-series-race-results/
A9: 2025_R08_GOODYEAR_400 | B9: 2025 | C9: 8 | D9: Goodyear 400 | E9: 45753 | F9: Darlington Raceway | G9: Darlington, SC | H9: Intermediate/egg-shaped | I9: Completed | J9: Denny Hamlin | K9: https://www.jayski.com/nascar-cup-series/2025-nascar-cup-series-race-results/
A10: 2025_R09_FOOD_CITY_500 | B10: 2025 | C10: 9 | D10: Food City 500 | E10: 45760 | F10: Bristol Motor Speedway | G10: Bristol, TN | H10: Short track | I10: Completed | J10: Kyle Larson | K10: https://www.jayski.com/nascar-cup-series/2025-nascar-cup-series-race-results/
A11: 2025_R10_JACK_LINK_S_500 | B11: 2025 | C11: 10 | D11: Jack Link's 500 | E11: 45774 | F11: Talladega Superspeedway | G11: Lincoln, AL | H11: Superspeedway | I11: Completed | J11: Austin Cindric | K11: https://www.jayski.com/nascar-cup-series/2025-nascar-cup-series-race-results/
A12: 2025_R11_WURTH_400 | B12: 2025 | C12: 11 | D12: Wurth 400 | E12: 45781 | F12: Texas Motor Speedway | G12: Fort Worth, TX | H12: Intermediate | I12: Completed | J12: Joey Logano | K12: https://www.jayski.com/nascar-cup-series/2025-nascar-cup-series-race-results/
A13: 2025_R12_ADVENTHEALTH_400 | B13: 2025 | C13: 12 | D13: AdventHealth 400 | E13: 45788 | F13: Kansas Speedway | G13: Kansas City, KS | H13: Intermediate | I13: Completed | J13: Kyle Larson | K13: https://www.jayski.com/nascar-cup-series/2025-nascar-cup-series-race-results/
... A57: 2026_R20_QUAKER_STATE_400 | B57: 2026 | C57: 20 | D57: Quaker State 400 | E57: 46215 | F57: EchoPark Speedway | G57: Hampton, GA | H57: Drafting intermediate | I57: Completed | J57: Ryan Blaney | K57: https://www.jayski.com/nascar-cup-series/2026-nascar-cup-series-race-results/
A58: 2026_R21_WINDOW_WORLD_450 | B58: 2026 | C58: 21 | D58: Window World 450 | E58: 46222 | F58: North Wilkesboro Speedway | G58: North Wilkesboro, NC | H58: Short track | I58: Scheduled | K58: https://www.jayski.com/nascar-cup-series/2026-nascar-cup-series-race-results/
A59: 2026_R22_BRICKYARD_400 | B59: 2026 | C59: 22 | D59: Brickyard 400 | E59: 46229 | F59: Indianapolis Motor Speedway | G59: Speedway, IN | H59: Flat oval | I59: Scheduled | K59: https://www.jayski.com/nascar-cup-series/2026-nascar-cup-series-race-results/
A60: 2026_R23_IOWA_CORN_350 | B60: 2026 | C60: 23 | D60: Iowa Corn 350 | E60: 46243 | F60: Iowa Speedway | G60: Newton, IA | H60: Short/flat | I60: Scheduled | K60: https://www.jayski.com/nascar-cup-series/2026-nascar-cup-series-race-results/
A61: 2026_R24_COOK_OUT_400 | B61: 2026 | C61: 24 | D61: Cook Out 400 | E61: 46249 | F61: Richmond Raceway | G61: Richmond, VA | H61: Short track | I61: Scheduled | K61: https://www.jayski.com/nascar-cup-series/2026-nascar-cup-series-race-results/
A62: 2026_R25_DOLLAR_TREE_301 | B62: 2026 | C62: 25 | D62: Dollar Tree 301 | E62: 46257 | F62: New Hampshire Motor Speedway | G62: Loudon, NH | H62: Short/flat | I62: Scheduled | K62: https://www.jayski.com/nascar-cup-series/2026-nascar-cup-series-race-results/
A63: 2026_R26_COKE_ZERO_SUGAR_400 | B63: 2026 | C63: 26 | D63: Coke Zero Sugar 400 | E63: 46263 | F63: Daytona International Speedway | G63: Daytona Beach, FL | H63: Superspeedway | I63: Scheduled | K63: https://www.jayski.com/nascar-cup-series/2026-nascar-cup-series-race-results/
A64: 2026_R27_COOK_OUT_SOUTHERN_500 | B64: 2026 | C64: 27 | D64: Cook Out Southern 500 | E64: 46271 | F64: Darlington Raceway | G64: Darlington, SC | H64: Intermediate/egg-shaped | I64: Scheduled | K64: https://www.jayski.com/nascar-cup-series/2026-nascar-cup-series-race-results/
A65: 2026_R28_ENJOY_ILLINOIS_300 | B65: 2026 | C65: 28 | D65: Enjoy Illinois 300 | E65: 46278 | F65: World Wide Technology Raceway | G65: Madison, IL | H65: Flat intermediate | I65: Scheduled | K65: https://www.jayski.com/nascar-cup-series/2026-nascar-cup-series-race-results/
A66: 2026_R29_BASS_PRO_SHOPS_NIGHT_RACE | B66: 2026 | C66: 29 | D66: Bass Pro Shops Night Race | E66: 46284 | F66: Bristol Motor Speedway | G66: Bristol, TN | H66: Short track | I66: Scheduled | K66: https://www.jayski.com/nascar-cup-series/2026-nascar-cup-series-race-results/
A67: 2026_R30_HOLLYWOOD_CASINO_400 | B67: 2026 | C67: 30 | D67: Hollywood Casino 400 | E67: 46292 | F67: Kansas Speedway | G67: Kansas City, KS | H67: Intermediate | I67: Scheduled | K67: https://www.jayski.com/nascar-cup-series/2026-nascar-cup-series-race-results/
A68: 2026_R31_SOUTH_POINT_400 | B68: 2026 | C68: 31 | D68: South Point 400 | E68: 46299 | F68: Las Vegas Motor Speedway | G68: Las Vegas, NV | H68: Intermediate | I68: Scheduled | K68: https://www.jayski.com/nascar-cup-series/2026-nascar-cup-series-race-results/
A69: 2026_R32_BANK_OF_AMERICA_400 | B69: 2026 | C69: 32 | D69: Bank of America 400 | E69: 46306 | F69: Charlotte Motor Speedway ROVAL | G69: Concord, NC | H69: Road course | I69: Scheduled | K69: https://www.jayski.com/nascar-cup-series/2026-nascar-cup-series-race-results/
... A73: 2026_R36_NASCAR_CUP_SERIES_CHAMPIONSHIP | B73: 2026 | C73: 36 | D73: NASCAR Cup Series Championship | E73: 46334 | F73: Homestead-Miami Speedway | G73: Homestead, FL | H73: Intermediate | I73: Scheduled | K73: https://www.jayski.com/nascar-cup-series/2026-nascar-cup-series-race-results/

Sheet Drivers_by_Season
A1: Season | B1: Rank_Proxy | C1: Driver | D1: Car_No | E1: Team | F1: Manufacturer | G1: Notes | H1: Source_URL
A2: 2025 | B2: 1 | C2: Kyle Larson | D2: 5 | E2: Hendrick Motorsports | F2: Chevrolet | G2: 2025 champion; elite intermediate/short-track form | H2: https://www.jayski.com/nascar-cup-series/2025-nascar-cup-series-race-results/
A3: 2025 | B3: 2 | C3: Denny Hamlin | D3: 11 | E3: Joe Gibbs Racing | F3: Toyota | G3: Elite veteran; 2026 points leader after EchoPark | H3: https://www.jayski.com/nascar-cup-series/2025-nascar-cup-series-race-results/
A4: 2025 | B4: 3 | C4: Chase Briscoe | D4: 19 | E4: Joe Gibbs Racing | F4: Toyota | G4: 2025/2026 wins; strong qualifying/pole narratives | H4: https://www.jayski.com/nascar-cup-series/2025-nascar-cup-series-race-results/
A5: 2025 | B5: 4 | C5: William Byron | D5: 24 | E5: Hendrick Motorsports | F5: Chevrolet | G5: 2025 Daytona and regular-season champion profile | H5: https://www.jayski.com/nascar-cup-series/2025-nascar-cup-series-race-results/
A6: 2025 | B6: 5 | C6: Christopher Bell | D6: 20 | E6: Joe Gibbs Racing | F6: Toyota | G6: 2025 early win streak; strong short/road/intermediate profile | H6: https://www.jayski.com/nascar-cup-series/2025-nascar-cup-series-race-results/
A7: 2025 | B7: 6 | C7: Ryan Blaney | D7: 12 | E7: Team Penske | F7: Ford | G7: Penske lead; 2025 Championship race winner, 2026 EchoPark winner | H7: https://www.jayski.com/nascar-cup-series/2025-nascar-cup-series-race-results/
A8: 2025 | B8: 7 | C8: Chase Elliott | D8: 9 | E8: Hendrick Motorsports | F8: Chevrolet | G8: Hendrick driver; strong road/short track profile | H8: https://www.jayski.com/nascar-cup-series/2025-nascar-cup-series-race-results/
A9: 2025 | B9: 8 | C9: Tyler Reddick | D9: 45 | E9: 23XI Racing | F9: Toyota | G9: Elite 2026 form; multiple early wins and road-course skill | H9: https://www.jayski.com/nascar-cup-series/2025-nascar-cup-series-race-results/
A10: 2025 | B10: 9 | C10: Joey Logano | D10: 22 | E10: Team Penske | F10: Ford | G10: Penske veteran; superspeedway/flat-track profile | H10: https://www.jayski.com/nascar-cup-series/2025-nascar-cup-series-race-results/
A11: 2025 | B11: 10 | C11: Shane van Gisbergen | D11: 97 | E11: Trackhouse Racing | F11: Chevrolet | G11: Road-course specialist; multiple road/street wins | H11: https://www.jayski.com/nascar-cup-series/2025-nascar-cup-series-race-results/
A12: 2025 | B12: 11 | C12: Bubba Wallace | D12: 23 | E12: 23XI Racing | F12: Toyota | G12: Superspeedway/intermediate upside; 2025 Brickyard winner | H12: https://www.jayski.com/nascar-cup-series/2025-nascar-cup-series-race-results/
A13: 2025 | B13: 12 | C13: Ross Chastain | D13: 1 | E13: Trackhouse Racing | F13: Chevrolet | G13: Charlotte/Coke 600 2025 winner | H13: https://www.jayski.com/nascar-cup-series/2025-nascar-cup-series-race-results/
... A65: 2026 | B65: 32 | C65: Austin Dillon | D65: 3 | E65: Richard Childress Racing | F65: Chevrolet | G65: Short-track/plate race upside; 2025 Richmond winner | H65: https://www.nascar.com/standings/nascar-cup-series/

Sheet Source_Inventory
A1: Source_ID | B1: Race_Key | C1: Season | D1: Round | E1: Race | F1: Race_Date | G1: Tier | H1: Outlet | I1: Source_Type | J1: Link_Type | K1: Description | L1: Primary_Features | M1: Search_Query | N1: URL | O1: Coding_Status | P1: Notes
A2: 2025_R01_DAYTONA_500_S01 | B2: 2025_R01_DAYTONA_500 | C2: 2025 | D2: 1 | E2: Daytona 500 | F2: 45704 | G2: Tier 1 | H2: Jayski | I2: Cup race results / race hub | J2: Direct source | K2: Race results, pole, entry list, practice/qualifying links. | L2: Results / entry / practice / qualifying | N2: https://www.jayski.com/nascar-cup-series/2025-nascar-cup-series-race-results/ | O2: Retained target | P2: Primary race hub source.
A3: 2025_R01_DAYTONA_500_S02 | B3: 2025_R01_DAYTONA_500 | C3: 2025 | D3: 1 | E3: Daytona 500 | F3: 45704 | G3: Tier 1 | H3: NASCAR.com | I3: Official NASCAR race page/recap | J3: Search target | K3: Official recap, winners gallery, standings, race results. | L3: Race recap / standings / official results | M3: site:nascar.com 2025 Daytona 500 NASCAR Cup preview odds favorites recap | N3: https://www.nascar.com/ | O3: Search target | P3: Use to capture pre-race narrative, practice/qualifying, and post-race recap.
A4: 2025_R01_DAYTONA_500_S03 | B4: 2025_R01_DAYTONA_500 | C4: 2025 | D4: 1 | E4: Daytona 500 | F4: 45704 | G4: Tier 1 | H4: Racing-Reference | I4: Race year / results reference | J4: Direct source | K4: Season results and standings reference. | L4: Results/reference | N4: https://www.racing-reference.info/raceyear/2025/W | O4: Retained target | P4: Useful for backfill and validation.
A5: 2025_R01_DAYTONA_500_S04 | B5: 2025_R01_DAYTONA_500 | C5: 2025 | D5: 1 | E5: Daytona 500 | F5: 45704 | G5: Tier 2 | H5: Odds/Betting Articles | I5: Winner odds / market favorites | J5: Search target | K5: Pre-race winner odds and favorites if available from DraftKings/FanDuel/Action/Rotowire/etc. | L5: Odds favorite / market move | M5: 2025 Daytona 500 NASCAR Cup winner odds favorites DraftKings FanDuel | O5: Search target | P5: Use when model wants odds-based chatter/market signal.
A6: 2025_R01_DAYTONA_500_S05 | B6: 2025_R01_DAYTONA_500 | C6: 2025 | D6: 1 | E6: Daytona 500 | F6: 45704 | G6: Tier 2 | H6: Team/driver/news articles | I6: Pre-race chatter/articles | J6: Search target | K6: Driver quotes, team confidence, practice/qualifying notes, upgrades, penalties, weather. | L6: Momentum / context / track fit | M6: 2025 Daytona 500 NASCAR Cup preview driver quotes practice qualifying tire strategy | O6: Search target | P6: Manual coding target.
A7: 2025_R02_AMBETTER_HEALTH_400_S01 | B7: 2025_R02_AMBETTER_HEALTH_400 | C7: 2025 | D7: 2 | E7: Ambetter Health 400 | F7: 45711 | G7: Tier 1 | H7: Jayski | I7: Cup race results / race hub | J7: Direct source | K7: Race results, pole, entry list, practice/qualifying links. | L7: Results / entry / practice / qualifying | N7: https://www.jayski.com/nascar-cup-series/2025-nascar-cup-series-race-results/ | O7: Retained target | P7: Primary race hub source.
A8: 2025_R02_AMBETTER_HEALTH_400_S02 | B8: 2025_R02_AMBETTER_HEALTH_400 | C8: 2025 | D8: 2 | E8: Ambetter Health 400 | F8: 45711 | G8: Tier 1 | H8: NASCAR.com | I8: Official NASCAR race page/recap | J8: Search target | K8: Official recap, winners gallery, standings, race results. | L8: Race recap / standings / official results | M8: site:nascar.com 2025 Ambetter Health 400 NASCAR Cup preview odds favorites recap | N8: https://www.nascar.com/ | O8: Search target | P8: Use to capture pre-race narrative, practice/qualifying, and post-race recap.
A9: 2025_R02_AMBETTER_HEALTH_400_S03 | B9: 2025_R02_AMBETTER_HEALTH_400 | C9: 2025 | D9: 2 | E9: Ambetter Health 400 | F9: 45711 | G9: Tier 1 | H9: Racing-Reference | I9: Race year / results reference | J9: Direct source | K9: Season results and standings reference. | L9: Results/reference | N9: https://www.racing-reference.info/raceyear/2025/W | O9: Retained target | P9: Useful for backfill and validation.
A10: 2025_R02_AMBETTER_HEALTH_400_S04 | B10: 2025_R02_AMBETTER_HEALTH_400 | C10: 2025 | D10: 2 | E10: Ambetter Health 400 | F10: 45711 | G10: Tier 2 | H10: Odds/Betting Articles | I10: Winner odds / market favorites | J10: Search target | K10: Pre-race winner odds and favorites if available from DraftKings/FanDuel/Action/Rotowire/etc. | L10: Odds favorite / market move | M10: 2025 Ambetter Health 400 NASCAR Cup winner odds favorites DraftKings FanDuel | O10: Search target | P10: Use when model wants odds-based chatter/market signal.
A11: 2025_R02_AMBETTER_HEALTH_400_S05 | B11: 2025_R02_AMBETTER_HEALTH_400 | C11: 2025 | D11: 2 | E11: Ambetter Health 400 | F11: 45711 | G11: Tier 2 | H11: Team/driver/news articles | I11: Pre-race chatter/articles | J11: Search target | K11: Driver quotes, team confidence, practice/qualifying notes, upgrades, penalties, weather. | L11: Momentum / context / track fit | M11: 2025 Ambetter Health 400 NASCAR Cup preview driver quotes practice qualifying tire strategy | O11: Search target | P11: Manual coding target.
A12: 2025_R03_ECHOPARK_TEXAS_GRAND_PRIX_S01 | B12: 2025_R03_ECHOPARK_TEXAS_GRAND_PRIX | C12: 2025 | D12: 3 | E12: EchoPark Texas Grand Prix | F12: 45718 | G12: Tier 1 | H12: Jayski | I12: Cup race results / race hub | J12: Direct source | K12: Race results, pole, entry list, practice/qualifying links. | L12: Results / entry / practice / qualifying | N12: https://www.jayski.com/nascar-cup-series/2025-nascar-cup-series-race-results/ | O12: Retained target | P12: Primary race hub source.
A13: 2025_R03_ECHOPARK_TEXAS_GRAND_PRIX_S02 | B13: 2025_R03_ECHOPARK_TEXAS_GRAND_PRIX | C13: 2025 | D13: 3 | E13: EchoPark Texas Grand Prix | F13: 45718 | G13: Tier 1 | H13: NASCAR.com | I13: Official NASCAR race page/recap | J13: Search target | K13: Official recap, winners gallery, standings, race results. | L13: Race recap / standings / official results | M13: site:nascar.com 2025 EchoPark Texas Grand Prix NASCAR Cup preview odds favorites recap | N13: https://www.nascar.com/ | O13: Search target | P13: Use to capture pre-race narrative, practice/qualifying, and post-race recap.
A14: 2025_R03_ECHOPARK_TEXAS_GRAND_PRIX_S03 | B14: 2025_R03_ECHOPARK_TEXAS_GRAND_PRIX | C14: 2025 | D14: 3 | E14: EchoPark Texas Grand Prix | F14: 45718 | G14: Tier 1 | H14: Racing-Reference | I14: Race year / results reference | J14: Direct source | K14: Season results and standings reference. | L14: Results/reference | N14: https://www.racing-reference.info/raceyear/2025/W | O14: Retained target | P14: Useful for backfill and validation.
A15: 2025_R03_ECHOPARK_TEXAS_GRAND_PRIX_S04 | B15: 2025_R03_ECHOPARK_TEXAS_GRAND_PRIX | C15: 2025 | D15: 3 | E15: EchoPark Texas Grand Prix | F15: 45718 | G15: Tier 2 | H15: Odds/Betting Articles | I15: Winner odds / market favorites | J15: Search target | K15: Pre-race winner odds and favorites if available from DraftKings/FanDuel/Action/Rotowire/etc. | L15: Odds favorite / market move | M15: 2025 EchoPark Texas Grand Prix NASCAR Cup winner odds favorites DraftKings FanDuel | O15: Search target | P15: Use when model wants odds-based chatter/market signal.
A16: 2025_R03_ECHOPARK_TEXAS_GRAND_PRIX_S05 | B16: 2025_R03_ECHOPARK_TEXAS_GRAND_PRIX | C16: 2025 | D16: 3 | E16: EchoPark Texas Grand Prix | F16: 45718 | G16: Tier 2 | H16: Team/driver/news articles | I16: Pre-race chatter/articles | J16: Search target | K16: Driver quotes, team confidence, practice/qualifying notes, upgrades, penalties, weather. | L16: Momentum / context / track fit | M16: 2025 EchoPark Texas Grand Prix NASCAR Cup preview driver quotes practice qualifying tire strategy | O16: Search target | P16: Manual coding target.
A17: 2025_R04_SHRINERS_CHILDREN_S_500_S01 | B17: 2025_R04_SHRINERS_CHILDREN_S_500 | C17: 2025 | D17: 4 | E17: Shriners Children's 500 | F17: 45725 | G17: Tier 1 | H17: Jayski | I17: Cup race results / race hub | J17: Direct source | K17: Race results, pole, entry list, practice/qualifying links. | L17: Results / entry / practice / qualifying | N17: https://www.jayski.com/nascar-cup-series/2025-nascar-cup-series-race-results/ | O17: Retained target | P17: Primary race hub source.
A18: 2025_R04_SHRINERS_CHILDREN_S_500_S02 | B18: 2025_R04_SHRINERS_CHILDREN_S_500 | C18: 2025 | D18: 4 | E18: Shriners Children's 500 | F18: 45725 | G18: Tier 1 | H18: NASCAR.com | I18: Official NASCAR race page/recap | J18: Search target | K18: Official recap, winners gallery, standings, race results. | L18: Race recap / standings / official results | M18: site:nascar.com 2025 Shriners Children's 500 NASCAR Cup preview odds favorites recap | N18: https://www.nascar.com/ | O18: Search target | P18: Use to capture pre-race narrative, practice/qualifying, and post-race recap.
A19: 2025_R04_SHRINERS_CHILDREN_S_500_S03 | B19: 2025_R04_SHRINERS_CHILDREN_S_500 | C19: 2025 | D19: 4 | E19: Shriners Children's 500 | F19: 45725 | G19: Tier 1 | H19: Racing-Reference | I19: Race year / results reference | J19: Direct source | K19: Season results and standings reference. | L19: Results/reference | N19: https://www.racing-reference.info/raceyear/2025/W | O19: Retained target | P19: Useful for backfill and validation.
A20: 2025_R04_SHRINERS_CHILDREN_S_500_S04 | B20: 2025_R04_SHRINERS_CHILDREN_S_500 | C20: 2025 | D20: 4 | E20: Shriners Children's 500 | F20: 45725 | G20: Tier 2 | H20: Odds/Betting Articles | I20: Winner odds / market favorites | J20: Search target | K20: Pre-race winner odds and favorites if available from DraftKings/FanDuel/Action/Rotowire/etc. | L20: Odds favorite / market move | M20: 2025 Shriners Children's 500 NASCAR Cup winner odds favorites DraftKings FanDuel | O20: Search target | P20: Use when model wants odds-based chatter/market signal.
A21: 2025_R04_SHRINERS_CHILDREN_S_500_S05 | B21: 2025_R04_SHRINERS_CHILDREN_S_500 | C21: 2025 | D21: 4 | E21: Shriners Children's 500 | F21: 45725 | G21: Tier 2 | H21: Team/driver/news articles | I21: Pre-race chatter/articles | J21: Search target | K21: Driver quotes, team confidence, practice/qualifying notes, upgrades, penalties, weather. | L21: Momentum / context / track fit | M21: 2025 Shriners Children's 500 NASCAR Cup preview driver quotes practice qualifying tire strategy | O21: Search target | P21: Manual coding target.
A22: 2025_R05_PENNZOIL_400_S01 | B22: 2025_R05_PENNZOIL_400 | C22: 2025 | D22: 5 | E22: Pennzoil 400 | F22: 45732 | G22: Tier 1 | H22: Jayski | I22: Cup race results / race hub | J22: Direct source | K22: Race results, pole, entry list, practice/qualifying links. | L22: Results / entry / practice / qualifying | N22: https://www.jayski.com/nascar-cup-series/2025-nascar-cup-series-race-results/ | O22: Retained target | P22: Primary race hub source.
A23: 2025_R05_PENNZOIL_400_S02 | B23: 2025_R05_PENNZOIL_400 | C23: 2025 | D23: 5 | E23: Pennzoil 400 | F23: 45732 | G23: Tier 1 | H23: NASCAR.com | I23: Official NASCAR race page/recap | J23: Search target | K23: Official recap, winners gallery, standings, race results. | L23: Race recap / standings / official results | M23: site:nascar.com 2025 Pennzoil 400 NASCAR Cup preview odds favorites recap | N23: https://www.nascar.com/ | O23: Search target | P23: Use to capture pre-race narrative, practice/qualifying, and post-race recap.
A24: 2025_R05_PENNZOIL_400_S03 | B24: 2025_R05_PENNZOIL_400 | C24: 2025 | D24: 5 | E24: Pennzoil 400 | F24: 45732 | G24: Tier 1 | H24: Racing-Reference | I24: Race year / results reference | J24: Direct source | K24: Season results and standings reference. | L24: Results/reference | N24: https://www.racing-reference.info/raceyear/2025/W | O24: Retained target | P24: Useful for backfill and validation.
A25: 2025_R05_PENNZOIL_400_S04 | B25: 2025_R05_PENNZOIL_400 | C25: 2025 | D25: 5 | E25: Pennzoil 400 | F25: 45732 | G25: Tier 2 | H25: Odds/Betting Articles | I25: Winner odds / market favorites | J25: Search target | K25: Pre-race winner odds and favorites if available from DraftKings/FanDuel/Action/Rotowire/etc. | L25: Odds favorite / market move | M25: 2025 Pennzoil 400 NASCAR Cup winner odds favorites DraftKings FanDuel | O25: Search target | P25: Use when model wants odds-based chatter/market signal.
A26: 2025_R05_PENNZOIL_400_S05 | B26: 2025_R05_PENNZOIL_400 | C26: 2025 | D26: 5 | E26: Pennzoil 400 | F26: 45732 | G26: Tier 2 | H26: Team/driver/news articles | I26: Pre-race chatter/articles | J26: Search target | K26: Driver quotes, team confidence, practice/qualifying notes, upgrades, penalties, weather. | L26: Momentum / context / track fit | M26: 2025 Pennzoil 400 NASCAR Cup preview driver quotes practice qualifying tire strategy | O26: Search target | P26: Manual coding target.
A27: 2025_R06_STRAIGHT_TALK_WIRELESS_400_S01 | B27: 2025_R06_STRAIGHT_TALK_WIRELESS_400 | C27: 2025 | D27: 6 | E27: Straight Talk Wireless 400 | F27: 45739 | G27: Tier 1 | H27: Jayski | I27: Cup race results / race hub | J27: Direct source | K27: Race results, pole, entry list, practice/qualifying links. | L27: Results / entry / practice / qualifying | N27: https://www.jayski.com/nascar-cup-series/2025-nascar-cup-series-race-results/ | O27: Retained target | P27: Primary race hub source.
A28: 2025_R06_STRAIGHT_TALK_WIRELESS_400_S02 | B28: 2025_R06_STRAIGHT_TALK_WIRELESS_400 | C28: 2025 | D28: 6 | E28: Straight Talk Wireless 400 | F28: 45739 | G28: Tier 1 | H28: NASCAR.com | I28: Official NASCAR race page/recap | J28: Search target | K28: Official recap, winners gallery, standings, race results. | L28: Race recap / standings / official results | M28: site:nascar.com 2025 Straight Talk Wireless 400 NASCAR Cup preview odds favorites recap | N28: https://www.nascar.com/ | O28: Search target | P28: Use to capture pre-race narrative, practice/qualifying, and post-race recap.
A29: 2025_R06_STRAIGHT_TALK_WIRELESS_400_S03 | B29: 2025_R06_STRAIGHT_TALK_WIRELESS_400 | C29: 2025 | D29: 6 | E29: Straight Talk Wireless 400 | F29: 45739 | G29: Tier 1 | H29: Racing-Reference | I29: Race year / results reference | J29: Direct source | K29: Season results and standings reference. | L29: Results/reference | N29: https://www.racing-reference.info/raceyear/2025/W | O29: Retained target | P29: Useful for backfill and validation.
A30: 2025_R06_STRAIGHT_TALK_WIRELESS_400_S04 | B30: 2025_R06_STRAIGHT_TALK_WIRELESS_400 | C30: 2025 | D30: 6 | E30: Straight Talk Wireless 400 | F30: 45739 | G30: Tier 2 | H30: Odds/Betting Articles | I30: Winner odds / market favorites | J30: Search target | K30: Pre-race winner odds and favorites if available from DraftKings/FanDuel/Action/Rotowire/etc. | L30: Odds favorite / market move | M30: 2025 Straight Talk Wireless 400 NASCAR Cup winner odds favorites DraftKings FanDuel | O30: Search target | P30: Use when model wants odds-based chatter/market signal.
A31: 2025_R06_STRAIGHT_TALK_WIRELESS_400_S05 | B31: 2025_R06_STRAIGHT_TALK_WIRELESS_400 | C31: 2025 | D31: 6 | E31: Straight Talk Wireless 400 | F31: 45739 | G31: Tier 2 | H31: Team/driver/news articles | I31: Pre-race chatter/articles | J31: Search target | K31: Driver quotes, team confidence, practice/qualifying notes, upgrades, penalties, weather. | L31: Momentum / context / track fit | M31: 2025 Straight Talk Wireless 400 NASCAR Cup preview driver quotes practice qualifying tire strategy | O31: Search target | P31: Manual coding target.
A32: 2025_R07_COOK_OUT_400_S01 | B32: 2025_R07_COOK_OUT_400 | C32: 2025 | D32: 7 | E32: Cook Out 400 | F32: 45746 | G32: Tier 1 | H32: Jayski | I32: Cup race results / race hub | J32: Direct source | K32: Race results, pole, entry list, practice/qualifying links. | L32: Results / entry / practice / qualifying | N32: https://www.jayski.com/nascar-cup-series/2025-nascar-cup-series-race-results/ | O32: Retained target | P32: Primary race hub source.
A33: 2025_R07_COOK_OUT_400_S02 | B33: 2025_R07_COOK_OUT_400 | C33: 2025 | D33: 7 | E33: Cook Out 400 | F33: 45746 | G33: Tier 1 | H33: NASCAR.com | I33: Official NASCAR race page/recap | J33: Search target | K33: Official recap, winners gallery, standings, race results. | L33: Race recap / standings / official results | M33: site:nascar.com 2025 Cook Out 400 NASCAR Cup preview odds favorites recap | N33: https://www.nascar.com/ | O33: Search target | P33: Use to capture pre-race narrative, practice/qualifying, and post-race recap.
A34: 2025_R07_COOK_OUT_400_S03 | B34: 2025_R07_COOK_OUT_400 | C34: 2025 | D34: 7 | E34: Cook Out 400 | F34: 45746 | G34: Tier 1 | H34: Racing-Reference | I34: Race year / results reference | J34: Direct source | K34: Season results and standings reference. | L34: Results/reference | N34: https://www.racing-reference.info/raceyear/2025/W | O34: Retained target | P34: Useful for backfill and validation.
A35: 2025_R07_COOK_OUT_400_S04 | B35: 2025_R07_COOK_OUT_400 | C35: 2025 | D35: 7 | E35: Cook Out 400 | F35: 45746 | G35: Tier 2 | H35: Odds/Betting Articles | I35: Winner odds / market favorites | J35: Search target | K35: Pre-race winner odds and favorites if available from DraftKings/FanDuel/Action/Rotowire/etc. | L35: Odds favorite / market move | M35: 2025 Cook Out 400 NASCAR Cup winner odds favorites DraftKings FanDuel | O35: Search target | P35: Use when model wants odds-based chatter/market signal.
A36: 2025_R07_COOK_OUT_400_S05 | B36: 2025_R07_COOK_OUT_400 | C36: 2025 | D36: 7 | E36: Cook Out 400 | F36: 45746 | G36: Tier 2 | H36: Team/driver/news articles | I36: Pre-race chatter/articles | J36: Search target | K36: Driver quotes, team confidence, practice/qualifying notes, upgrades, penalties, weather. | L36: Momentum / context / track fit | M36: 2025 Cook Out 400 NASCAR Cup preview driver quotes practice qualifying tire strategy | O36: Search target | P36: Manual coding target.
A37: 2025_R08_GOODYEAR_400_S01 | B37: 2025_R08_GOODYEAR_400 | C37: 2025 | D37: 8 | E37: Goodyear 400 | F37: 45753 | G37: Tier 1 | H37: Jayski | I37: Cup race results / race hub | J37: Direct source | K37: Race results, pole, entry list, practice/qualifying links. | L37: Results / entry / practice / qualifying | N37: https://www.jayski.com/nascar-cup-series/2025-nascar-cup-series-race-results/ | O37: Retained target | P37: Primary race hub source.
A38: 2025_R08_GOODYEAR_400_S02 | B38: 2025_R08_GOODYEAR_400 | C38: 2025 | D38: 8 | E38: Goodyear 400 | F38: 45753 | G38: Tier 1 | H38: NASCAR.com | I38: Official NASCAR race page/recap | J38: Search target | K38: Official recap, winners gallery, standings, race results. | L38: Race recap / standings / official results | M38: site:nascar.com 2025 Goodyear 400 NASCAR Cup preview odds favorites recap | N38: https://www.nascar.com/ | O38: Search target | P38: Use to capture pre-race narrative, practice/qualifying, and post-race recap.
A39: 2025_R08_GOODYEAR_400_S03 | B39: 2025_R08_GOODYEAR_400 | C39: 2025 | D39: 8 | E39: Goodyear 400 | F39: 45753 | G39: Tier 1 | H39: Racing-Reference | I39: Race year / results reference | J39: Direct source | K39: Season results and standings reference. | L39: Results/reference | N39: https://www.racing-reference.info/raceyear/2025/W | O39: Retained target | P39: Useful for backfill and validation.
A40: 2025_R08_GOODYEAR_400_S04 | B40: 2025_R08_GOODYEAR_400 | C40: 2025 | D40: 8 | E40: Goodyear 400 | F40: 45753 | G40: Tier 2 | H40: Odds/Betting Articles | I40: Winner odds / market favorites | J40: Search target | K40: Pre-race winner odds and favorites if available from DraftKings/FanDuel/Action/Rotowire/etc. | L40: Odds favorite / market move | M40: 2025 Goodyear 400 NASCAR Cup winner odds favorites DraftKings FanDuel | O40: Search target | P40: Use when model wants odds-based chatter/market signal.
...

Sheet Driver_Race_Signals
A1: Signal_ID | B1: Race_Key | C1: Season | D1: Round | E1: Race | F1: Race_Date | G1: Driver | H1: Momentum_Raw | I1: Track_Fit_Raw | J1: Context_Raw | K1: Source_Confidence | L1: Raw_Weighted_Score | M1: Composite_Chatter_Score | N1: Points_Nudge | O1: Finish_Position_Nudge | P1: Primary_Source_IDs | Q1: Coding_Notes | R1: Last_Coded | S1: Coded_By | T1: Race_Source_URL
A2: 2025_R01_DAYTONA_500_DENNY_HAMLIN | B2: 2025_R01_DAYTONA_500 | C2: 2025 | D2: 1 | E2: Daytona 500 | F2: 45704 | G2: Denny Hamlin | H2: 0.35 | I2: 0 | J2: 0 | K2: 0.75 | L2: =H2*Settings!$B$4+I2*Settings!$B$5+J2*Settings!$B$6 | M2: =MAX(-Settings!$B$7,MIN(Settings!$B$7,L2*K2)) | N2: =M2*Settings!$B$9 | O2: =-M2*Settings!$B$10 | P2: 2025_R01_DAYTONA_500_S01;2025_R01_DAYTONA_500_S04;2025_R01_DAYTONA_500_S05 | Q2: Proxy coded from results/form/track-fit scaffold; review against pre-race article/odds before modeling. | R2: 2026-07-15 | S2: GPT-5.5 Thinking | T2: https://www.jayski.com/nascar-cup-series/2025-nascar-cup-series-race-results/
A3: 2025_R01_DAYTONA_500_TYLER_REDDICK | B3: 2025_R01_DAYTONA_500 | C3: 2025 | D3: 1 | E3: Daytona 500 | F3: 45704 | G3: Tyler Reddick | H3: 0.25 | I3: 0.35 | J3: 0 | K3: 0.75 | L3: =H3*Settings!$B$4+I3*Settings!$B$5+J3*Settings!$B$6 | M3: =MAX(-Settings!$B$7,MIN(Settings!$B$7,L3*K3)) | N3: =M3*Settings!$B$9 | O3: =-M3*Settings!$B$10 | P3: 2025_R01_DAYTONA_500_S01;2025_R01_DAYTONA_500_S04;2025_R01_DAYTONA_500_S05 | Q3: Proxy coded from results/form/track-fit scaffold; review against pre-race article/odds before modeling. | R3: 2026-07-15 | S3: GPT-5.5 Thinking | T3: https://www.jayski.com/nascar-cup-series/2025-nascar-cup-series-race-results/
A4: 2025_R01_DAYTONA_500_RYAN_BLANEY | B4: 2025_R01_DAYTONA_500 | C4: 2025 | D4: 1 | E4: Daytona 500 | F4: 45704 | G4: Ryan Blaney | H4: 0.25 | I4: 0.5 | J4: 0 | K4: 0.75 | L4: =H4*Settings!$B$4+I4*Settings!$B$5+J4*Settings!$B$6 | M4: =MAX(-Settings!$B$7,MIN(Settings!$B$7,L4*K4)) | N4: =M4*Settings!$B$9 | O4: =-M4*Settings!$B$10 | P4: 2025_R01_DAYTONA_500_S01;2025_R01_DAYTONA_500_S04;2025_R01_DAYTONA_500_S05 | Q4: Proxy coded from results/form/track-fit scaffold; review against pre-race article/odds before modeling. | R4: 2026-07-15 | S4: GPT-5.5 Thinking | T4: https://www.jayski.com/nascar-cup-series/2025-nascar-cup-series-race-results/
A5: 2025_R01_DAYTONA_500_TY_GIBBS | B5: 2025_R01_DAYTONA_500 | C5: 2025 | D5: 1 | E5: Daytona 500 | F5: 45704 | G5: Ty Gibbs | H5: 0.05 | I5: 0 | J5: 0 | K5: 0.75 | L5: =H5*Settings!$B$4+I5*Settings!$B$5+J5*Settings!$B$6 | M5: =MAX(-Settings!$B$7,MIN(Settings!$B$7,L5*K5)) | N5: =M5*Settings!$B$9 | O5: =-M5*Settings!$B$10 | P5: 2025_R01_DAYTONA_500_S01;2025_R01_DAYTONA_500_S04;2025_R01_DAYTONA_500_S05 | Q5: Proxy coded from results/form/track-fit scaffold; review against pre-race article/odds before modeling. | R5: 2026-07-15 | S5: GPT-5.5 Thinking | T5: https://www.jayski.com/nascar-cup-series/2025-nascar-cup-series-race-results/
A6: 2025_R01_DAYTONA_500_CHASE_ELLIOTT | B6: 2025_R01_DAYTONA_500 | C6: 2025 | D6: 1 | E6: Daytona 500 | F6: 45704 | G6: Chase Elliott | H6: 0.25 | I6: 0.35 | J6: 0 | K6: 0.75 | L6: =H6*Settings!$B$4+I6*Settings!$B$5+J6*Settings!$B$6 | M6: =MAX(-Settings!$B$7,MIN(Settings!$B$7,L6*K6)) | N6: =M6*Settings!$B$9 | O6: =-M6*Settings!$B$10 | P6: 2025_R01_DAYTONA_500_S01;2025_R01_DAYTONA_500_S04;2025_R01_DAYTONA_500_S05 | Q6: Proxy coded from results/form/track-fit scaffold; review against pre-race article/odds before modeling. | R6: 2026-07-15 | S6: GPT-5.5 Thinking | T6: https://www.jayski.com/nascar-cup-series/2025-nascar-cup-series-race-results/
A7: 2025_R01_DAYTONA_500_KYLE_LARSON | B7: 2025_R01_DAYTONA_500 | C7: 2025 | D7: 1 | E7: Daytona 500 | F7: 45704 | G7: Kyle Larson | H7: 0.35 | I7: 0 | J7: 0 | K7: 0.75 | L7: =H7*Settings!$B$4+I7*Settings!$B$5+J7*Settings!$B$6 | M7: =MAX(-Settings!$B$7,MIN(Settings!$B$7,L7*K7)) | N7: =M7*Settings!$B$9 | O7: =-M7*Settings!$B$10 | P7: 2025_R01_DAYTONA_500_S01;2025_R01_DAYTONA_500_S04;2025_R01_DAYTONA_500_S05 | Q7: Proxy coded from results/form/track-fit scaffold; review against pre-race article/odds before modeling. | R7: 2026-07-15 | S7: GPT-5.5 Thinking | T7: https://www.jayski.com/nascar-cup-series/2025-nascar-cup-series-race-results/
A8: 2025_R01_DAYTONA_500_CHRISTOPHER_BELL | B8: 2025_R01_DAYTONA_500 | C8: 2025 | D8: 1 | E8: Daytona 500 | F8: 45704 | G8: Christopher Bell | H8: 0.35 | I8: 0 | J8: 0 | K8: 0.75 | L8: =H8*Settings!$B$4+I8*Settings!$B$5+J8*Settings!$B$6 | M8: =MAX(-Settings!$B$7,MIN(Settings!$B$7,L8*K8)) | N8: =M8*Settings!$B$9 | O8: =-M8*Settings!$B$10 | P8: 2025_R01_DAYTONA_500_S01;2025_R01_DAYTONA_500_S04;2025_R01_DAYTONA_500_S05 | Q8: Proxy coded from results/form/track-fit scaffold; review against pre-race article/odds before modeling. | R8: 2026-07-15 | S8: GPT-5.5 Thinking | T8: https://www.jayski.com/nascar-cup-series/2025-nascar-cup-series-race-results/
A9: 2025_R01_DAYTONA_500_WILLIAM_BYRON | B9: 2025_R01_DAYTONA_500 | C9: 2025 | D9: 1 | E9: Daytona 500 | F9: 45704 | G9: William Byron | H9: 0.95 | I9: 0.35 | J9: 0 | K9: 0.75 | L9: =H9*Settings!$B$4+I9*Settings!$B$5+J9*Settings!$B$6 | M9: =MAX(-Settings!$B$7,MIN(Settings!$B$7,L9*K9)) | N9: =M9*Settings!$B$9 | O9: =-M9*Settings!$B$10 | P9: 2025_R01_DAYTONA_500_S01;2025_R01_DAYTONA_500_S04;2025_R01_DAYTONA_500_S05 | Q9: Proxy coded from results/form/track-fit scaffold; review against pre-race article/odds before modeling. | R9: 2026-07-15 | S9: GPT-5.5 Thinking | T9: https://www.jayski.com/nascar-cup-series/2025-nascar-cup-series-race-results/
A10: 2025_R01_DAYTONA_500_CHASE_BRISCOE | B10: 2025_R01_DAYTONA_500 | C10: 2025 | D10: 1 | E10: Daytona 500 | F10: 45704 | G10: Chase Briscoe | H10: 0.35 | I10: 0 | J10: 0 | K10: 0.75 | L10: =H10*Settings!$B$4+I10*Settings!$B$5+J10*Settings!$B$6 | M10: =MAX(-Settings!$B$7,MIN(Settings!$B$7,L10*K10)) | N10: =M10*Settings!$B$9 | O10: =-M10*Settings!$B$10 | P10: 2025_R01_DAYTONA_500_S01;2025_R01_DAYTONA_500_S04;2025_R01_DAYTONA_500_S05 | Q10: Proxy coded from results/form/track-fit scaffold; review against pre-race article/odds before modeling. | R10: 2026-07-15 | S10: GPT-5.5 Thinking | T10: https://www.jayski.com/nascar-cup-series/2025-nascar-cup-series-race-results/
A11: 2025_R01_DAYTONA_500_SHANE_VAN_GISBERGEN | B11: 2025_R01_DAYTONA_500 | C11: 2025 | D11: 1 | E11: Daytona 500 | F11: 45704 | G11: Shane van Gisbergen | H11: 0.25 | I11: 0 | J11: 0 | K11: 0.75 | L11: =H11*Settings!$B$4+I11*Settings!$B$5+J11*Settings!$B$6 | M11: =MAX(-Settings!$B$7,MIN(Settings!$B$7,L11*K11)) | N11: =M11*Settings!$B$9 | O11: =-M11*Settings!$B$10 | P11: 2025_R01_DAYTONA_500_S01;2025_R01_DAYTONA_500_S04;2025_R01_DAYTONA_500_S05 | Q11: Proxy coded from results/form/track-fit scaffold; review against pre-race article/odds before modeling. | R11: 2026-07-15 | S11: GPT-5.5 Thinking | T11: https://www.jayski.com/nascar-cup-series/2025-nascar-cup-series-race-results/
A12: 2025_R01_DAYTONA_500_ROSS_CHASTAIN | B12: 2025_R01_DAYTONA_500 | C12: 2025 | D12: 1 | E12: Daytona 500 | F12: 45704 | G12: Ross Chastain | H12: 0.15 | I12: 0 | J12: 0 | K12: 0.75 | L12: =H12*Settings!$B$4+I12*Settings!$B$5+J12*Settings!$B$6 | M12: =MAX(-Settings!$B$7,MIN(Settings!$B$7,L12*K12)) | N12: =M12*Settings!$B$9 | O12: =-M12*Settings!$B$10 | P12: 2025_R01_DAYTONA_500_S01;2025_R01_DAYTONA_500_S04;2025_R01_DAYTONA_500_S05 | Q12: Proxy coded from results/form/track-fit scaffold; review against pre-race article/odds before modeling. | R12: 2026-07-15 | S12: GPT-5.5 Thinking | T12: https://www.jayski.com/nascar-cup-series/2025-nascar-cup-series-race-results/
A13: 2025_R01_DAYTONA_500_BUBBA_WALLACE | B13: 2025_R01_DAYTONA_500 | C13: 2025 | D13: 1 | E13: Daytona 500 | F13: 45704 | G13: Bubba Wallace | H13: 0.15 | I13: 0.5 | J13: 0 | K13: 0.75 | L13: =H13*Settings!$B$4+I13*Settings!$B$5+J13*Settings!$B$6 | M13: =MAX(-Settings!$B$7,MIN(Settings!$B$7,L13*K13)) | N13: =M13*Settings!$B$9 | O13: =-M13*Settings!$B$10 | P13: 2025_R01_DAYTONA_500_S01;2025_R01_DAYTONA_500_S04;2025_R01_DAYTONA_500_S05 | Q13: Proxy coded from results/form/track-fit scaffold; review against pre-race article/odds before modeling. | R13: 2026-07-15 | S13: GPT-5.5 Thinking | T13: https://www.jayski.com/nascar-cup-series/2025-nascar-cup-series-race-results/
... A2305: 2026_R36_NASCAR_CUP_SERIES_CHAMPIONSHIP_COLE_CUSTER | B2305: 2026_R36_NASCAR_CUP_SERIES_CHAMPIONSHIP | C2305: 2026 | D2305: 36 | E2305: NASCAR Cup Series Championship | F2305: 46334 | G2305: Cole Custer | H2305: -0.05 | I2305: 0 | J2305: 0 | K2305: 0.6 | L2305: =H2305*Settings!$B$4+I2305*Settings!$B$5+J2305*Settings!$B$6 | M2305: =MAX(-Settings!$B$7,MIN(Settings!$B$7,L2305*K2305)) | N2305: =M2305*Settings!$B$9 | O2305: =-M2305*Settings!$B$10 | P2305: 2026_R36_NASCAR_CUP_SERIES_CHAMPIONSHIP_S01;2026_R36_NASCAR_CUP_SERIES_CHAMPIONSHIP_S04;2026_R36_NASCAR_CUP_SERIES_CHAMPIONSHIP_S05 | Q2305: Proxy coded from results/form/track-fit scaffold; review against pre-race article/odds before modeling. | R2305: 2026-07-15 | S2305: GPT-5.5 Thinking | T2305: https://www.jayski.com/nascar-cup-series/2026-nascar-cup-series-race-results/

Sheet Scoring_Backtest
A1: NASCAR Chatter Scoring Backtest Setup
A2: Join this workbook to your NASCAR projection outputs.
A4: Item | B4: Value | C4: Notes
A5: Status | B5: Ready for backtest once base model residuals are pasted/joined.
A6: Recommended first fit | B6: Residual ~ alpha + beta * Composite_Chatter_Score | C6: A single coefficient is more robust than sparse separate bucket dummies.
A7: Join keys | B7: Season + Round + Driver | C7: Race_Key is also available.
A8: Suggested test | B8: Compare Brier/log-loss or ranked finishing residuals with and without chatter nudge.
A9: Caution | B9: Scores are proxy-coded and should be validated against true pre-race timestamped articles/odds before being used as production model inputs.

Sheet Signal_Event_Log
A1: Event_ID | B1: Season | C1: Start_Round | D1: End_Round | E1: Driver | F1: Bucket | G1: Raw_Adjustment | H1: Evidence_Basis | I1: Source_Tier | J1: Source_URL_or_Search | K1: Notes
A2: EVT_0001 | B2: 2025 | C2: 2 | D2: 4 | E2: Christopher Bell | F2: Momentum | G2: 1.2 | H2: Three consecutive wins early in 2025: Atlanta/COTA/Phoenix. | I2: Jayski results | J2: https://www.jayski.com/nascar-cup-series/2025-nascar-cup-series-race-results/ | K2: High positive momentum in the immediate period.
A3: EVT_0002 | B3: 2025 | C3: 6 | D3: 12 | E3: Kyle Larson | F3: Momentum | G3: 0.9 | H3: Dominant spring form with Homestead, Bristol and Kansas wins; 2025 champion outcome. | I3: Jayski results / NASCAR playoffs | J3: https://www.jayski.com/nascar-cup-series/2025-nascar-cup-series-race-results/
A4: EVT_0003 | B4: 2025 | C4: 7 | D4: 15 | E4: Denny Hamlin | F4: Momentum | G4: 0.8 | H4: Multiple wins in spring/summer, including Martinsville/Darlington/Michigan. | I4: Jayski results | J4: https://www.jayski.com/nascar-cup-series/2025-nascar-cup-series-race-results/
A5: EVT_0004 | B5: 2025 | C5: 16 | D5: 24 | E5: Shane van Gisbergen | F5: Track_Fit | G5: 1.5 | H5: Road/street course dominance beginning Mexico and extending through Chicago/Sonoma/Watkins Glen. | I5: Jayski results | J5: https://www.jayski.com/nascar-cup-series/2025-nascar-cup-series-race-results/ | K5: Apply mostly on road/street courses.
A6: EVT_0005 | B6: 2025 | C6: 17 | D6: 34 | E6: Chase Briscoe | F6: Momentum | G6: 0.7 | H6: Briscoe won Pocono, Southern 500 and Talladega plus strong late-season pole/run narratives. | I6: Jayski results | J6: https://www.jayski.com/nascar-cup-series/2025-nascar-cup-series-race-results/
A7: EVT_0006 | B7: 2025 | C7: 26 | D7: 36 | E7: Ryan Blaney | F7: Momentum | G7: 0.8 | H7: Strong late-season profile; Daytona, New Hampshire and Championship race wins. | I7: Jayski results | J7: https://www.jayski.com/nascar-cup-series/2025-nascar-cup-series-race-results/
A8: EVT_0007 | B8: 2025 | C8: 22 | D8: 26 | E8: Bubba Wallace | F8: Momentum | G8: 0.5 | H8: Brickyard 400 win and superspeedway/intermediate upside. | I8: Jayski results | J8: https://www.jayski.com/nascar-cup-series/2025-nascar-cup-series-race-results/
A9: EVT_0008 | B9: 2026 | C9: 1 | D9: 10 | E9: Tyler Reddick | F9: Momentum | G9: 1.4 | H9: Reddick opened 2026 with five wins through Kansas: Daytona, Atlanta, COTA, Darlington, Kansas. | I9: Jayski/NASCAR winners | J9: https://www.nascar.com/gallery/2026-nascar-cup-series-winners/ | K9: Very strong positive start.
A10: EVT_0009 | B10: 2026 | C10: 5 | D10: 20 | E10: Denny Hamlin | F10: Momentum | G10: 0.9 | H10: Hamlin led 2026 points after EchoPark with four wins per NASCAR/ESPN snippets and Jayski race results. | I10: NASCAR standings / Jayski | J10: https://www.nascar.com/standings/nascar-cup-series/
A11: EVT_0010 | B11: 2026 | C11: 12 | D11: 18 | E11: Shane van Gisbergen | F11: Track_Fit | G11: 1.4 | H11: Road-course wins at Watkins Glen and Sonoma plus pole strength. | I11: Jayski/NASCAR winners | J11: https://www.nascar.com/gallery/2026-nascar-cup-series-winners/ | K11: High track-fit driver on road/street courses.
A12: EVT_0011 | B12: 2026 | C12: 19 | D12: 21 | E12: Ryan Blaney | F12: Momentum | G12: 0.8 | H12: Blaney won EchoPark after earlier Phoenix win; positive short-term momentum into North Wilkesboro. | I12: NASCAR race recap / Jayski | J12: https://www.nascar.com/news-media/2026/07/12/2026-cup-series-echopark-summer-recap-results/
A13: EVT_0012 | B13: 2026 | C13: 19 | D13: 21 | E13: Chase Briscoe | F13: Momentum | G13: 0.6 | H13: Briscoe won Chicagoland in 2026 and had strong qualifying-related narratives. | I13: Jayski results | J13: https://www.jayski.com/nascar-cup-series/2026-nascar-cup-series-race-results/
A14: EVT_0013 | B14: 2026 | C14: 8 | D14: 12 | E14: Ty Gibbs | F14: Momentum | G14: 0.5 | H14: Gibbs won Bristol and entered 2026 midseason as a top-five points driver. | I14: Jayski / ESPN standings | J14: https://www.jayski.com/nascar-cup-series/2026-nascar-cup-series-race-results/
A15: EVT_0014 | B15: 2026 | C15: 10 | D15: 12 | E15: Carson Hocevar | F15: Momentum | G15: 0.5 | H15: Hocevar won Talladega and had emerging-upside signal. | I15: Jayski results | J15: https://www.jayski.com/nascar-cup-series/2026-nascar-cup-series-race-results/
A16: EVT_0015 | B16: 2026 | C16: 17 | D16: 18 | E16: Corey Heim | F16: Momentum | G16: 0.6 | H16: Heim won the Naval Base Coronado street race. | I16: Jayski/NASCAR winners | J16: https://www.nascar.com/gallery/2026-nascar-cup-series-winners/

Sheet Scoring_Methodology
A1: NASCAR Pre-Race Chatter Scoring Methodology
A2: Low-hanging, audit-friendly driver-level chatter score.
A4: Topic | B4: Method | C4: Notes
A5: Purpose | B5: Fill the Driver_Race_Signals matrix with a model nudge using pre-race chatter, odds/source targets, track fit, and recent form.
A6: Unit | B6: Driver-race | C6: NASCAR is driver-centered for model outputs; team/manufacturer can be added later if needed.
A7: Sources | B7: Tier 1: NASCAR.com, Jayski, Racing-Reference. Tier 2: betting odds articles, driver/team media, previews. | C7: Source URLs and search queries retained in Source_Inventory.
A8: Momentum | B8: Recent wins, strong points form, positive media narrative, team speed. | C8: Event log applies obvious streaks and winning form.
A9: Track Fit | B9: Road-course specialists, superspeedway specialists, short-track/intermediate strengths. | C9: Track type is embedded in Race_Index.
A10: Context Bundle | B10: Practice/qualifying, injury/penalty/weather/reliability, driver quotes. | C10: Mostly left for manual update after pre-race article review.
A11: Confidence | B11: Higher confidence where an event has explicit source basis; lower for scheduled races without source review.
A12: Recommended use | B12: Export CSV_Output and fit one coefficient to model residuals first. | C12: Do not overfit separate bucket coefficients until enough history is accumulated.

Sheet Signal_Summary
A1: NASCAR Chatter Scoring Summary
A2: Formula-driven summary of current scoring scaffold.
A4: Season | B4: Driver-Race Rows | C4: Avg Composite | D4: Event-Coded % | E4: Avg Confidence | F4: Max Composite | G4: Min Composite
A5: 2025 | B5: =COUNTIF(Driver_Race_Signals!$C:$C,A5) | C5: =AVERAGEIF(Driver_Race_Signals!$C:$C,A5,Driver_Race_Signals!$M:$M) | D5: =COUNTIFS(Driver_Race_Signals!$C:$C,A5,Driver_Race_Signals!$P:$P,"EVT*")/B5 | E5: =AVERAGEIF(Driver_Race_Signals!$C:$C,A5,Driver_Race_Signals!$K:$K) | F5: =MAXIFS(Driver_Race_Signals!$M:$M,Driver_Race_Signals!$C:$C,A5) | G5: =MINIFS(Driver_Race_Signals!$M:$M,Driver_Race_Signals!$C:$C,A5)
A6: 2026 | B6: =COUNTIF(Driver_Race_Signals!$C:$C,A6) | C6: =AVERAGEIF(Driver_Race_Signals!$C:$C,A6,Driver_Race_Signals!$M:$M) | D6: =COUNTIFS(Driver_Race_Signals!$C:$C,A6,Driver_Race_Signals!$P:$P,"EVT*")/B6 | E6: =AVERAGEIF(Driver_Race_Signals!$C:$C,A6,Driver_Race_Signals!$K:$K) | F6: =MAXIFS(Driver_Race_Signals!$M:$M,Driver_Race_Signals!$C:$C,A6) | G6: =MINIFS(Driver_Race_Signals!$M:$M,Driver_Race_Signals!$C:$C,A6)

Sheet CSV_Output
A1: signal_id | B1: race_key | C1: season | D1: round | E1: race | F1: race_date | G1: driver | H1: momentum_raw | I1: track_fit_raw | J1: context_raw | K1: source_confidence | L1: composite_chatter_score | M1: points_nudge | N1: finish_position_nudge | O1: source_ids | P1: coding_notes
A2: =Driver_Race_Signals!A2 | B2: =Driver_Race_Signals!B2 | C2: =Driver_Race_Signals!C2 | D2: =Driver_Race_Signals!D2 | E2: =Driver_Race_Signals!E2 | F2: =Driver_Race_Signals!F2 | G2: =Driver_Race_Signals!G2 | H2: =Driver_Race_Signals!H2 | ... K2: =Driver_Race_Signals!K2 | L2: =Driver_Race_Signals!M2 | M2: =Driver_Race_Signals!N2 | N2: =Driver_Race_Signals!O2 | O2: =Driver_Race_Signals!P2 | P2: =Driver_Race_Signals!Q2
A3: =Driver_Race_Signals!A3 | B3: =Driver_Race_Signals!B3 | C3: =Driver_Race_Signals!C3 | D3: =Driver_Race_Signals!D3 | E3: =Driver_Race_Signals!E3 | F3: =Driver_Race_Signals!F3 | G3: =Driver_Race_Signals!G3 | H3: =Driver_Race_Signals!H3 | ... K3: =Driver_Race_Signals!K3 | L3: =Driver_Race_Signals!M3 | M3: =Driver_Race_Signals!N3 | N3: =Driver_Race_Signals!O3 | O3: =Driver_Race_Signals!P3 | P3: =Driver_Race_Signals!Q3
A4: =Driver_Race_Signals!A4 | B4: =Driver_Race_Signals!B4 | C4: =Driver_Race_Signals!C4 | D4: =Driver_Race_Signals!D4 | E4: =Driver_Race_Signals!E4 | F4: =Driver_Race_Signals!F4 | G4: =Driver_Race_Signals!G4 | H4: =Driver_Race_Signals!H4 | ... K4: =Driver_Race_Signals!K4 | L4: =Driver_Race_Signals!M4 | M4: =Driver_Race_Signals!N4 | N4: =Driver_Race_Signals!O4 | O4: =Driver_Race_Signals!P4 | P4: =Driver_Race_Signals!Q4
A5: =Driver_Race_Signals!A5 | B5: =Driver_Race_Signals!B5 | C5: =Driver_Race_Signals!C5 | D5: =Driver_Race_Signals!D5 | E5: =Driver_Race_Signals!E5 | F5: =Driver_Race_Signals!F5 | G5: =Driver_Race_Signals!G5 | H5: =Driver_Race_Signals!H5 | ... K5: =Driver_Race_Signals!K5 | L5: =Driver_Race_Signals!M5 | M5: =Driver_Race_Signals!N5 | N5: =Driver_Race_Signals!O5 | O5: =Driver_Race_Signals!P5 | P5: =Driver_Race_Signals!Q5
A6: =Driver_Race_Signals!A6 | B6: =Driver_Race_Signals!B6 | C6: =Driver_Race_Signals!C6 | D6: =Driver_Race_Signals!D6 | E6: =Driver_Race_Signals!E6 | F6: =Driver_Race_Signals!F6 | G6: =Driver_Race_Signals!G6 | H6: =Driver_Race_Signals!H6 | ... K6: =Driver_Race_Signals!K6 | L6: =Driver_Race_Signals!M6 | M6: =Driver_Race_Signals!N6 | N6: =Driver_Race_Signals!O6 | O6: =Driver_Race_Signals!P6 | P6: =Driver_Race_Signals!Q6
A7: =Driver_Race_Signals!A7 | B7: =Driver_Race_Signals!B7 | C7: =Driver_Race_Signals!C7 | D7: =Driver_Race_Signals!D7 | E7: =Driver_Race_Signals!E7 | F7: =Driver_Race_Signals!F7 | G7: =Driver_Race_Signals!G7 | H7: =Driver_Race_Signals!H7 | ... K7: =Driver_Race_Signals!K7 | L7: =Driver_Race_Signals!M7 | M7: =Driver_Race_Signals!N7 | N7: =Driver_Race_Signals!O7 | O7: =Driver_Race_Signals!P7 | P7: =Driver_Race_Signals!Q7
A8: =Driver_Race_Signals!A8 | B8: =Driver_Race_Signals!B8 | C8: =Driver_Race_Signals!C8 | D8: =Driver_Race_Signals!D8 | E8: =Driver_Race_Signals!E8 | F8: =Driver_Race_Signals!F8 | G8: =Driver_Race_Signals!G8 | H8: =Driver_Race_Signals!H8 | ... K8: =Driver_Race_Signals!K8 | L8: =Driver_Race_Signals!M8 | M8: =Driver_Race_Signals!N8 | N8: =Driver_Race_Signals!O8 | O8: =Driver_Race_Signals!P8 | P8: =Driver_Race_Signals!Q8
A9: =Driver_Race_Signals!A9 | B9: =Driver_Race_Signals!B9 | C9: =Driver_Race_Signals!C9 | D9: =Driver_Race_Signals!D9 | E9: =Driver_Race_Signals!E9 | F9: =Driver_Race_Signals!F9 | G9: =Driver_Race_Signals!G9 | H9: =Driver_Race_Signals!H9 | ... K9: =Driver_Race_Signals!K9 | L9: =Driver_Race_Signals!M9 | M9: =Driver_Race_Signals!N9 | N9: =Driver_Race_Signals!O9 | O9: =Driver_Race_Signals!P9 | P9: =Driver_Race_Signals!Q9
A10: =Driver_Race_Signals!A10 | B10: =Driver_Race_Signals!B10 | C10: =Driver_Race_Signals!C10 | D10: =Driver_Race_Signals!D10 | E10: =Driver_Race_Signals!E10 | F10: =Driver_Race_Signals!F10 | G10: =Driver_Race_Signals!G10 | H10: =Driver_Race_Signals!H10 | ... K10: =Driver_Race_Signals!K10 | L10: =Driver_Race_Signals!M10 | M10: =Driver_Race_Signals!N10 | N10: =Driver_Race_Signals!O10 | O10: =Driver_Race_Signals!P10 | P10: =Driver_Race_Signals!Q10
A11: =Driver_Race_Signals!A11 | B11: =Driver_Race_Signals!B11 | C11: =Driver_Race_Signals!C11 | D11: =Driver_Race_Signals!D11 | E11: =Driver_Race_Signals!E11 | F11: =Driver_Race_Signals!F11 | G11: =Driver_Race_Signals!G11 | H11: =Driver_Race_Signals!H11 | ... K11: =Driver_Race_Signals!K11 | L11: =Driver_Race_Signals!M11 | M11: =Driver_Race_Signals!N11 | N11: =Driver_Race_Signals!O11 | O11: =Driver_Race_Signals!P11 | P11: =Driver_Race_Signals!Q11
A12: =Driver_Race_Signals!A12 | B12: =Driver_Race_Signals!B12 | C12: =Driver_Race_Signals!C12 | D12: =Driver_Race_Signals!D12 | E12: =Driver_Race_Signals!E12 | F12: =Driver_Race_Signals!F12 | G12: =Driver_Race_Signals!G12 | H12: =Driver_Race_Signals!H12 | ... K12: =Driver_Race_Signals!K12 | L12: =Driver_Race_Signals!M12 | M12: =Driver_Race_Signals!N12 | N12: =Driver_Race_Signals!O12 | O12: =Driver_Race_Signals!P12 | P12: =Driver_Race_Signals!Q12
A13: =Driver_Race_Signals!A13 | B13: =Driver_Race_Signals!B13 | C13: =Driver_Race_Signals!C13 | D13: =Driver_Race_Signals!D13 | E13: =Driver_Race_Signals!E13 | F13: =Driver_Race_Signals!F13 | G13: =Driver_Race_Signals!G13 | H13: =Driver_Race_Signals!H13 | ... K13: =Driver_Race_Signals!K13 | L13: =Driver_Race_Signals!M13 | M13: =Driver_Race_Signals!N13 | N13: =Driver_Race_Signals!O13 | O13: =Driver_Race_Signals!P13 | P13: =Driver_Race_Signals!Q13
... A2305: =Driver_Race_Signals!A2305 | B2305: =Driver_Race_Signals!B2305 | C2305: =Driver_Race_Signals!C2305 | D2305: =Driver_Race_Signals!D2305 | E2305: =Driver_Race_Signals!E2305 | F2305: =Driver_Race_Signals!F2305 | G2305: =Driver_Race_Signals!G2305 | H2305: =Driver_Race_Signals!H2305 | ... K2305: =Driver_Race_Signals!K2305 | L2305: =Driver_Race_Signals!M2305 | M2305: =Driver_Race_Signals!N2305 | N2305: =Driver_Race_Signals!O2305 | O2305: =Driver_Race_Signals!P2305 | P2305: =Driver_Race_Signals!Q2305
